Workbook

Sheet Tracking Marketing
A1: No | B1: Bahan Baku | C1: PT Sreya Sewu | I1: PT Central Proteina | O1: CJ Feed | X1: PT Charoen Pokpahand Indonesia | AD1: PT. Dinamika Megatama Citra | AG1: PT Haida | AJ1: PT Cargill | AM1: PT Matahari Sakti | AP1: PT New Hope | AV1: PT Wonokoyo | BB1: PT Japfa | BE1: PT Thai Union | BH1: PT De Heus | BK1: PT CPgP | BN1: PT Evergreen | BQ1: PT East Hope | BT1: PT. Malindo | BZ1: PT. Havindo | CC1: PT. Panca Patriot Prima | CF1: PT Sido Agung Farm | CI1: PT Gold Coin | CL1: PT Mulia Harvest
C2: Sidoarjo | F2: Balaraja | I2: Dupak | L2: Sepanjang | O2: Jombang | R2: Semarang | U2: Serang | X2: Sidoarjo | AA2: Semarang | AD2: Jombang | AG2: Pasuruan | AJ2: Pasuruan | AM2: Margomulyo | AP2: Sidoajo | AS2: Mojosari | AV2: Jawa Timur | AY2: Cikande | BB2: Grobogan | BE2: Lamongan | BH2: Jakarta | BK2: Cikampek | BN2: Pasuruan | BQ2: Pasuruan | BT2: Gresik | BW2: Grobogan | BZ2: Grobogan | CC2: Grobogan | CF2: Magelang | CI2: Margomulyo | CL2: Grobogan
C3: Post | D3: Present | E3: Cause | F3: Post | G3: Present | H3: Cause | I3: Post | J3: Present | K3: Cause | L3: Post | M3: Present | N3: Cause | O3: Post | P3: Present | Q3: Cause | R3: Post | S3: Present | T3: Cause | U3: Post | V3: Present | W3: Cause | X3: Post | Y3: Present | Z3: Cause | AA3: Post | AB3: Present | AC3: Cause | AD3: Post | AE3: Present | AF3: Cause | AG3: Post | AH3: Present | AI3: Cause | AJ3: Post | AK3: Present | AL3: Cause | AM3: Post | AN3: Present | AO3: Cause | AP3: Post | AQ3: Present | AR3: Cause | AS3: Post | AT3: Present | AU3: Cause | AV3: Post | AW3: Present | AX3: Cause | AY3: Post | AZ3: Present | BA3: Cause | BB3: Post | BC3: Present | BD3: Cause | BE3: Post | BF3: Present | BG3: Cause | BH3: Post | BI3: Present | BJ3: Cause | BK3: Post | BL3: Present | BM3: Cause | BN3: Post | BO3: Present | BP3: Cause | BQ3: Post | BR3: Present | BS3: Cause | BT3: Post | BU3: Present | BV3: Cause | BW3: Post | BX3: Present | BY3: Cause | BZ3: Post | CA3: Present | CB3: Cause | CC3: Post | CD3: Present | CE3: Cause | CF3: Post | CG3: Present | CH3: Cause | CI3: Post | CJ3: Present | CK3: Cause | CL3: Post | CM3: Present | CN3: Cause
A4: 1 | B4: Mie Kuning | C4: TRUE | D4: Ready | F4: FALSE | I4: FALSE | L4: FALSE | O4: FALSE | P4: Confirmed | R4: FALSE | U4: FALSE | X4: FALSE | AA4: FALSE | AD4: FALSE | AG4: TRUE | AH4: Ready | AJ4: FALSE | AM4: FALSE | AP4: FALSE | AS4: FALSE | AV4: FALSE | AY4: TRUE | AZ4: Confirmed | BB4: FALSE | BE4: FALSE | BH4: FALSE | BK4: FALSE | BN4: FALSE | BQ4: TRUE | BR4: Negotiate | BT4: TRUE | BU4: Ready | BW4: FALSE | BZ4: FALSE | CC4: FALSE | CF4: FALSE | CI4: TRUE | CJ4: Confirmed | CL4: FALSE
A5: 2 | B5: Mie Merah | C5: FALSE | F5: FALSE | I5: FALSE | L5: FALSE | O5: FALSE | P5: Confirmed | R5: FALSE | U5: FALSE | X5: FALSE | AA5: FALSE | AD5: FALSE | AG5: TRUE | AH5: Not Reasonable Price | AJ5: FALSE | AM5: FALSE | AP5: TRUE | AQ5: Not Reasonable Price | AS5: TRUE | AT5: Not Updated Yet | AV5: FALSE | AY5: FALSE | BB5: FALSE | BE5: FALSE | BH5: FALSE | BK5: FALSE | BN5: FALSE | BQ5: TRUE | BR5: Confirmed | BT5: TRUE | BU5: Confirmed | BW5: FALSE | BZ5: FALSE | CC5: FALSE | CF5: FALSE | CI5: TRUE | CJ5: Confirmed | CL5: FALSE
A6: 3 | B6: Tepung Biskuit | C6: TRUE | D6: Ready | F6: TRUE | G6: Po's Closed | I6: FALSE | L6: FALSE | O6: TRUE | P6: Ready | R6: TRUE | S6: Ready | U6: TRUE | V6: Ready | X6: TRUE | Y6: Not used | Z6: Sedang musim Panen jagung. harga jagung tidak mahal | AA6: TRUE | AB6: Not used | AD6: FALSE | AG6: TRUE | AH6: Sample Sent! | AJ6: TRUE | AK6: Not Qualified Raw | AM6: TRUE | AN6: Ready | AP6: FALSE | AQ6: Not used | AS6: TRUE | AT6: Ready | AU6: Kondisi Pabrik Hold | AV6: TRUE | AW6: Not used | AY6: FALSE | BB6: TRUE | BC6: Sample Sent! | BE6: FALSE | BH6: TRUE | BI6: Confirmed | BK6: FALSE | BN6: FALSE | BQ6: TRUE | BR6: Confirmed | BT6: FALSE | BU6: Sample Sent! | BW6: TRUE | BX6: Not Updated Yet | BY6: Belum ada respon sama sekali | BZ6: FALSE | CC6: TRUE | CD6: Confirmed | CF6: TRUE | CG6: Ready | CI6: TRUE | CJ6: Confirmed | CL6: TRUE | CM6: Sample Sent!
A7: 4 | B7: Katul | C7: TRUE | D7: Not Reasonable Price | F7: FALSE | I7: TRUE | J7: Ready | L7: TRUE | M7: Not Reasonable Price | O7: TRUE | P7: Ready | R7: FALSE | U7: TRUE | V7: Ready | X7: TRUE | Y7: Not Reasonable Price | AA7: TRUE | AB7: Not Reasonable Price | AD7: TRUE | AE7: Po's Closed | AG7: FALSE | AJ7: TRUE | AK7: Not Qualified Raw | AM7: TRUE | AN7: Ready | AP7: TRUE | AQ7: Confirmed | AS7: FALSE | AV7: FALSE | AY7: TRUE | AZ7: Confirmed | BB7: FALSE | BE7: TRUE | BF7: Not Reasonable Price | BH7: TRUE | BI7: Confirmed | BK7: TRUE | BL7: Confirmed | BM7: Terdapat 37 Vendor | BN7: TRUE | BO7: Not Qualified Raw | BQ7: FALSE | BR7: Confirmed | BT7: TRUE | BU7: Negotiate | BW7: FALSE | BZ7: TRUE | CA7: Confirmed | CB7: Harga 3300, margin hanya 11%. pembayaran lebih dari 3bulan | CC7: TRUE | CD7: Confirmed | CE7: Ambil dari Pabrik di Makasar | CF7: FALSE | CI7: TRUE | CJ7: Confirmed | CL7: TRUE | CM7: Not Reasonable Price
A8: 5 | B8: Bone Meal | C8: TRUE | D8: Ready | F8: TRUE | G8: Not Reasonable Price | H8: margin 3%, seharusnya minimal 7% | I8: FALSE | L8: FALSE | O8: FALSE | R8: FALSE | T8: Pabrik Belum Mau menerima | U8: FALSE | X8: FALSE | AA8: FALSE | AD8: FALSE | AG8: FALSE | AJ8: FALSE | AM8: FALSE | AP8: TRUE | AQ8: Not used | AS8: FALSE | AV8: TRUE | AW8: Sample Sent! | AY8: FALSE | BB8: FALSE | BE8: FALSE | BH8: FALSE | BK8: FALSE | BN8: FALSE | BQ8: FALSE | BT8: FALSE | BW8: FALSE | BZ8: FALSE | CC8: FALSE | CF8: TRUE | CI8: FALSE | CL8: FALSE
A9: 6 | B9: CFM/FTM | C9: TRUE | D9: Ready | F9: TRUE | G9: Ready | I9: FALSE | L9: TRUE | M9: Not Qualified Raw | O9: TRUE | P9: Ready | R9: TRUE | S9: Ready | U9: FALSE | X9: TRUE | Y9: Ready | AA9: TRUE | AB9: Not Reasonable Price | AD9: FALSE | AG9: FALSE | AJ9: FALSE | AM9: FALSE | AP9: TRUE | AQ9: Not used | AS9: FALSE | AV9: TRUE | AW9: Sample Sent! | AY9: TRUE | AZ9: Confirmed | BB9: FALSE | BE9: FALSE | BH9: TRUE | BI9: Confirmed | BK9: FALSE | BN9: FALSE | BQ9: FALSE | BT9: FALSE | BW9: FALSE | BZ9: FALSE | CC9: FALSE | CF9: TRUE | CI9: FALSE | CL9: FALSE
A10: 7 | B10: Garam | C10: TRUE | D10: Ready | F10: FALSE | I10: FALSE | L10: FALSE | O10: FALSE | R10: FALSE | U10: FALSE | X10: TRUE | Y10: Not Qualified Raw | Z10: Sedang mencari Spesifikasi yang sesuai | AA10: FALSE | AD10: FALSE | AG10: FALSE | AJ10: FALSE | AM10: FALSE | AP10: FALSE | AS10: FALSE | AV10: TRUE | AW10: Confirmed | AY10: FALSE | BB10: TRUE | BC10: Sample Sent! | BE10: FALSE | BH10: TRUE | BI10: Confirmed | BK10: FALSE | BN10: FALSE | BQ10: FALSE | BT10: FALSE | BW10: FALSE | BZ10: FALSE | CC10: FALSE | CF10: FALSE | CI10: FALSE | CL10: TRUE | CM10: Not Reasonable Price | CN10: harga PO 2500. harga supplier di 2525
A11: 8 | B11: Molases | C11: FALSE | F11: FALSE | I11: TRUE | J11: Po's Closed | L11: FALSE | O11: FALSE | R11: FALSE | U11: FALSE | X11: FALSE | AA11: TRUE | AB11: Not Reasonable Price | AD11: FALSE | AG11: FALSE | AJ11: FALSE | AM11: FALSE | AP11: FALSE | AS11: FALSE | AV11: FALSE | AY11: FALSE | BB11: FALSE | BE11: TRUE | BF11: Confirmed | BH11: FALSE | BK11: FALSE | BL11: Confirmed | BN11: TRUE | BO11: Confirmed | BQ11: FALSE | BT11: FALSE | BW11: FALSE | BZ11: FALSE | CC11: FALSE | CF11: FALSE | CI11: FALSE | CL11: FALSE
A12: 9 | B12: SHM | C12: FALSE | F12: FALSE | I12: TRUE | J12: Ready | L12: TRUE | M12: Not Qualified Raw | N12: Protein 40 up | O12: FALSE | R12: FALSE | U12: FALSE | X12: FALSE | AA12: FALSE | AD12: FALSE | AG12: FALSE | AJ12: FALSE | AM12: TRUE | AN12: Sample Sent! | AP12: FALSE | AS12: FALSE | AV12: FALSE | AY12: FALSE | BB12: FALSE | BE12: FALSE | BH12: FALSE | BK12: FALSE | BN12: TRUE | BO12: Not Qualified Raw | BQ12: FALSE | BT12: FALSE | BW12: FALSE | BZ12: FALSE | CC12: FALSE | CF12: FALSE | CI12: FALSE | CL12: FALSE
A13: 10 | B13: DSS | C13: FALSE | F13: FALSE | I13: TRUE | J13: Ready | L13: FALSE | O13: FALSE | R13: FALSE | U13: FALSE | X13: FALSE | AA13: FALSE | AD13: FALSE | AG13: FALSE | AJ13: FALSE | AM13: TRUE | AN13: Sample Sent! | AP13: FALSE | AS13: FALSE | AV13: FALSE | AY13: FALSE | BB13: FALSE | BE13: FALSE | BH13: FALSE | BK13: FALSE | BN13: FALSE | BQ13: FALSE | BT13: FALSE | BW13: FALSE | BZ13: FALSE | CC13: FALSE | CF13: FALSE | CI13: FALSE | CL13: FALSE
A14: 11 | B14: Menir | C14: FALSE | F14: FALSE | I14: TRUE | J14: Confirmed | L14: FALSE | O14: FALSE | R14: FALSE | U14: FALSE | X14: TRUE | Y14: Confirmed | AA14: FALSE | AD14: FALSE | AG14: FALSE | AJ14: TRUE | AK14: Confirmed | AM14: FALSE | AP14: FALSE | AS14: FALSE | AV14: FALSE | AY14: FALSE | BB14: FALSE | BE14: TRUE | BF14: Not used | BH14: FALSE | BK14: FALSE | BN14: FALSE | BQ14: FALSE | BT14: FALSE | BW14: FALSE | BZ14: TRUE | CA14: Confirmed | CC14: FALSE | CF14: FALSE | CI14: FALSE | CL14: FALSE
A15: 12 | B15: Copra | C15: TRUE | D15: Not Reasonable Price | F15: FALSE | I15: TRUE | J15: Factory No Need Yet | L15: TRUE | M15: Not Reasonable Price | O15: TRUE | P15: Not Reasonable Price | R15: FALSE | U15: FALSE | X15: FALSE | AA15: FALSE | AD15: FALSE | AG15: FALSE | AJ15: TRUE | AK15: Not Reasonable Price | AM15: TRUE | AN15: Confirmed | AP15: FALSE | AS15: FALSE | AV15: FALSE | AY15: FALSE | BB15: FALSE | BE15: FALSE | BH15: FALSE | BK15: TRUE | BL15: Confirmed | BN15: FALSE | BQ15: FALSE | BT15: FALSE | BW15: FALSE | BZ15: FALSE | CC15: FALSE | CF15: FALSE | CI15: FALSE | CL15: FALSE
A16: 13 | B16: PKD (Palm Kernel Dehulized ) | C16: TRUE | D16: Not used | F16: FALSE | I16: FALSE | L16: FALSE | O16: FALSE | R16: FALSE | U16: FALSE | X16: FALSE | AA16: FALSE | AD16: TRUE | AE16: Hold | AG16: FALSE | AJ16: FALSE | AM16: FALSE | AP16: FALSE | AS16: FALSE | AV16: FALSE | AY16: FALSE | BB16: FALSE | BE16: FALSE | BH16: FALSE | BK16: FALSE | BN16: FALSE | BQ16: FALSE | BT16: FALSE | BW16: FALSE | BZ16: FALSE | CC16: FALSE | CF16: FALSE | CI16: FALSE | CL16: FALSE
A17: 14 | B17: Biji Batu | C17: TRUE | D17: Not Reasonable Price | F17: FALSE | I17: FALSE | L17: FALSE | O17: FALSE | R17: FALSE | U17: FALSE | X17: TRUE | Y17: Confirmed | AA17: FALSE | AD17: FALSE | AG17: FALSE | AJ17: FALSE | AM17: FALSE | AP17: FALSE | AS17: FALSE | AV17: FALSE | AY17: FALSE | BB17: TRUE | BC17: Po's Closed | BE17: FALSE | BH17: FALSE | BK17: FALSE | BN17: FALSE | BQ17: FALSE | BT17: FALSE | BW17: FALSE | BZ17: FALSE | CC17: FALSE | CF17: FALSE | CI17: FALSE | CL17: FALSE
A18: 15 | B18: Tepung Batu | C18: TRUE | D18: Not Reasonable Price | F18: FALSE | I18: FALSE | L18: FALSE | O18: FALSE | R18: FALSE | U18: FALSE | X18: TRUE | Y18: Confirmed | AA18: FALSE | AD18: FALSE | AG18: FALSE | AJ18: FALSE | AM18: FALSE | AP18: FALSE | AS18: FALSE | AV18: FALSE | AY18: FALSE | BB18: FALSE | BE18: FALSE | BH18: FALSE | BK18: FALSE | BN18: TRUE | BO18: Not used | BQ18: FALSE | BT18: FALSE | BW18: FALSE | BZ18: FALSE | CC18: FALSE | CF18: FALSE | CI18: FALSE | CL18: FALSE
A19: 16 | B19: PKM | C19: FALSE | F19: FALSE | I19: FALSE | L19: FALSE | O19: FALSE | R19: FALSE | U19: FALSE | X19: TRUE | Y19: Confirmed | AA19: FALSE | AD19: FALSE | AG19: FALSE | AJ19: FALSE | AM19: FALSE | AP19: FALSE | AS19: FALSE | AV19: FALSE | AY19: FALSE | BB19: TRUE | BC19: Sample Sent! | BE19: FALSE | BH19: TRUE | BI19: Confirmed | BK19: TRUE | BL19: Confirmed | BN19: FALSE | BQ19: FALSE | BT19: FALSE | BW19: FALSE | BZ19: FALSE | CC19: FALSE | CF19: FALSE | CI19: FALSE | CL19: FALSE
A20: 17 | B20: Corn Gem | C20: TRUE | D20: Not Reasonable Price | F20: FALSE | I20: FALSE | L20: FALSE | O20: FALSE | R20: FALSE | U20: FALSE | X20: FALSE | AA20: FALSE | AD20: FALSE | AG20: FALSE | AJ20: FALSE | AM20: FALSE | AP20: TRUE | AQ20: Ready | AS20: FALSE | AV20: FALSE | AY20: FALSE | BB20: FALSE | BE20: FALSE | BH20: TRUE | BI20: Confirmed | BK20: FALSE | BN20: FALSE | BQ20: FALSE | BT20: FALSE | BW20: FALSE | BZ20: FALSE | CC20: FALSE | CF20: FALSE | CI20: FALSE | CL20: FALSE
A21: 18 | B21: Cangkang Kemiri | C21: TRUE | D21: Didn't Have Supplier | F21: FALSE | I21: FALSE | L21: FALSE | O21: FALSE | R21: FALSE | U21: FALSE | X21: FALSE | AA21: FALSE | AD21: FALSE | AG21: FALSE | AJ21: FALSE | AM21: FALSE | AP21: FALSE | AS21: FALSE | AV21: FALSE | AY21: FALSE | BB21: FALSE | BE21: TRUE | BF21: Confirmed | BH21: FALSE | BK21: FALSE | BN21: TRUE | BO21: Confirmed | BQ21: FALSE | BT21: FALSE | BW21: FALSE | BZ21: FALSE | CC21: FALSE | CF21: FALSE | CI21: FALSE | CL21: FALSE
A22: 19 | B22: Tepung Gaplek | C22: TRUE | D22: Not used | F22: FALSE | I22: FALSE | L22: FALSE | O22: FALSE | R22: FALSE | U22: FALSE | X22: FALSE | AA22: FALSE | AD22: FALSE | AG22: FALSE | AJ22: FALSE | AM22: FALSE | AP22: FALSE | AS22: FALSE | AV22: FALSE | AW22: Confirmed | AY22: FALSE | BB22: FALSE | BE22: FALSE | BH22: TRUE | BI22: Confirmed | BK22: FALSE | BN22: TRUE | BO22: Not Qualified Raw | BQ22: FALSE | BT22: FALSE | BW22: FALSE | BZ22: FALSE | CC22: FALSE | CF22: FALSE | CI22: TRUE | CJ22: Confirmed | CL22: FALSE
A23: 20 | B23: Kebi | C23: TRUE | D23: Not Qualified Raw | E23: Belum menemukan supplier yang sesuai | F23: FALSE | I23: FALSE | L23: FALSE | O23: FALSE | R23: FALSE | U23: FALSE | X23: FALSE | AA23: FALSE | AD23: TRUE | AE23: Po's Closed | AG23: FALSE | AJ23: FALSE | AM23: FALSE | AP23: TRUE | AQ23: Confirmed | AS23: FALSE | AV23: FALSE | AY23: FALSE | BB23: FALSE | BE23: FALSE | BH23: FALSE | BK23: FALSE | BN23: TRUE | BO23: Confirmed | BQ23: TRUE | BR23: Confirmed | BT23: FALSE | BW23: FALSE | BZ23: FALSE | CC23: FALSE | CF23: FALSE | CI23: FALSE | CL23: FALSE
A24: 21 | B24: Fish Meal | C24: FALSE | F24: FALSE | I24: FALSE | L24: FALSE | O24: FALSE | R24: FALSE | U24: FALSE | X24: FALSE | AA24: FALSE | AD24: FALSE | AG24: FALSE | AJ24: FALSE | AM24: FALSE | AP24: FALSE | AS24: FALSE | AV24: FALSE | AY24: FALSE | BB24: FALSE | BE24: TRUE | BF24: Didn't Have Supplier | BH24: FALSE | BK24: FALSE | BN24: FALSE | BQ24: FALSE | BT24: FALSE | BW24: FALSE | BZ24: FALSE | CC24: FALSE | CF24: FALSE | CI24: FALSE | CL24: FALSE
A25: 22 | B25: MBM (Meat Bone Meal) | C25: FALSE | F25: FALSE | I25: FALSE | L25: FALSE | O25: FALSE | R25: FALSE | U25: FALSE | X25: FALSE | AA25: FALSE | AD25: FALSE | AG25: FALSE | AJ25: FALSE | AM25: FALSE | AP25: FALSE | AS25: FALSE | AV25: FALSE | AY25: FALSE | BB25: FALSE | BE25: FALSE | BH25: TRUE | BI25: Confirmed | BK25: TRUE | BL25: Confirmed | BM25: Import | BN25: TRUE | BO25: Not Qualified Raw | BQ25: FALSE | BT25: FALSE | BW25: FALSE | BZ25: FALSE | CC25: TRUE | CD25: Confirmed | CE25: Impor | CF25: TRUE | CI25: FALSE | CL25: FALSE
A26: 23 | B26: Poultry Meal | C26: FALSE | F26: FALSE | I26: FALSE | L26: FALSE | O26: FALSE | R26: FALSE | U26: FALSE | X26: FALSE | AA26: FALSE | AD26: FALSE | AG26: FALSE | AJ26: FALSE | AM26: FALSE | AP26: FALSE | AS26: FALSE | AV26: FALSE | AY26: FALSE | BB26: FALSE | BE26: TRUE | BF26: Didn't Have Supplier | BH26: FALSE | BK26: FALSE | BN26: FALSE | BQ26: FALSE | BT26: FALSE | BW26: FALSE | BZ26: FALSE | CC26: FALSE | CF26: FALSE | CI26: FALSE | CL26: FALSE
A27: 24 | B27: Gaplek Chip | C27: FALSE | F27: FALSE | I27: FALSE | L27: FALSE | O27: FALSE | R27: FALSE | U27: FALSE | X27: FALSE | AA27: FALSE | AD27: FALSE | AG27: FALSE | AJ27: FALSE | AM27: FALSE | AP27: FALSE | AS27: FALSE | AV27: FALSE | AW27: Confirmed | AY27: FALSE | BB27: FALSE | BE27: FALSE | BH27: TRUE | BI27: Confirmed | BK27: TRUE | BL27: Not Reasonable Price | BM27: harga di 4000 | BN27: TRUE | BO27: Confirmed | BQ27: FALSE | BT27: FALSE | BW27: FALSE | BZ27: FALSE | CC27: FALSE | CF27: FALSE | CI27: FALSE | CL27: FALSE
A28: 25 | B28: Kepala Udang Utuh | C28: FALSE | F28: FALSE | I28: FALSE | L28: FALSE | O28: FALSE | R28: FALSE | U28: FALSE | X28: FALSE | AA28: FALSE | AD28: FALSE | AG28: FALSE | AJ28: FALSE | AM28: FALSE | AP28: FALSE | AS28: FALSE | AV28: FALSE | AY28: FALSE | BB28: FALSE | BE28: TRUE | BF28: Not used | BH28: FALSE | BK28: FALSE | BN28: FALSE | BQ28: FALSE | BT28: FALSE | BW28: FALSE | BZ28: FALSE | CC28: FALSE | CF28: FALSE | CI28: FALSE | CL28: FALSE
A29: 26 | B29: Tepung Roti/Bread Waste | C29: FALSE | F29: FALSE | I29: FALSE | L29: FALSE | O29: FALSE | R29: FALSE | U29: FALSE | X29: FALSE | AA29: FALSE | AD29: FALSE | AG29: FALSE | AJ29: TRUE | AK29: Not Qualified Raw | AL29: Menunggu kabar Pak Widodo | AM29: FALSE | AP29: FALSE | AS29: FALSE | AV29: FALSE | AY29: FALSE | BB29: FALSE | BE29: FALSE | BH29: FALSE | BK29: FALSE | BN29: FALSE | BQ29: FALSE | BT29: FALSE | BW29: FALSE | BZ29: FALSE | CC29: FALSE | CF29: FALSE | CI29: FALSE | CL29: FALSE
A30: 27 | B30: SG (Sekam Giling) | C30: TRUE | D30: Not used | F30: FALSE | I30: FALSE | L30: FALSE | O30: FALSE | P30: Confirmed | R30: FALSE | U30: FALSE | X30: TRUE | Y30: Sample Sent! | AA30: FALSE | AD30: FALSE | AG30: FALSE | AJ30: FALSE | AM30: FALSE | AP30: FALSE | AS30: FALSE | AV30: FALSE | AY30: FALSE | BB30: FALSE | BE30: FALSE | BH30: FALSE | BK30: FALSE | BN30: FALSE | BQ30: FALSE | BT30: FALSE | BW30: FALSE | BZ30: FALSE | CC30: FALSE | CF30: FALSE | CI30: FALSE | CL30: FALSE
A31: 28 | B31: Bran Gluten Feed (BGF) | C31: FALSE | F31: FALSE | I31: FALSE | L31: FALSE | O31: FALSE | R31: FALSE | U31: FALSE | X31: FALSE | AA31: FALSE | AD31: FALSE | AG31: FALSE | AJ31: FALSE | AM31: FALSE | AP31: FALSE | AS31: FALSE | AV31: FALSE | AY31: FALSE | BB31: FALSE | BE31: FALSE | BH31: FALSE | BK31: FALSE | BN31: FALSE | BQ31: FALSE | BT31: FALSE | BW31: FALSE | BZ31: FALSE | CC31: FALSE | CF31: FALSE | CI31: FALSE | CL31: FALSE
A32: 29 | B32: CGM | C32: FALSE | F32: FALSE | I32: FALSE | L32: FALSE | O32: FALSE | R32: FALSE | U32: FALSE | X32: TRUE | Y32: Sample Sent! | AA32: FALSE | AD32: FALSE | AG32: FALSE | AJ32: FALSE | AM32: FALSE | AP32: FALSE | AS32: FALSE | AV32: FALSE | AY32: FALSE | BB32: FALSE | BE32: FALSE | BH32: FALSE | BK32: FALSE | BN32: FALSE | BQ32: FALSE | BT32: FALSE | BW32: FALSE | BZ32: FALSE | CC32: TRUE | CD32: Confirmed | CE32: Impor | CF32: TRUE | CI32: FALSE | CL32: FALSE
A33: 30 | B33: CGF | C33: FALSE | F33: FALSE | I33: FALSE | L33: FALSE | O33: FALSE | R33: FALSE | U33: FALSE | X33: TRUE | Y33: Confirmed | Z33: belum bisa minta PO karena CPI order langsung dari pabrik | AA33: FALSE | AD33: FALSE | AG33: FALSE | AJ33: FALSE | AM33: FALSE | AP33: FALSE | AS33: FALSE | AV33: FALSE | AY33: FALSE | BB33: FALSE | BE33: FALSE | BH33: FALSE | BK33: FALSE | BN33: FALSE | BQ33: FALSE | BT33: FALSE | BW33: FALSE | BZ33: FALSE | CC33: FALSE | CF33: TRUE | CI33: FALSE | CL33: FALSE
A34: 31 | B34: Tepung Industri | C34: FALSE | F34: FALSE | I34: FALSE | L34: FALSE | O34: FALSE | R34: FALSE | U34: FALSE | X34: TRUE | Y34: Confirmed | AA34: FALSE | AD34: FALSE | AG34: FALSE | AJ34: FALSE | AM34: FALSE | AP34: FALSE | AS34: FALSE | AV34: FALSE | AY34: FALSE | BB34: FALSE | BE34: FALSE | BH34: FALSE | BK34: FALSE | BN34: FALSE | BQ34: FALSE | BT34: FALSE | BW34: FALSE | BZ34: FALSE | CC34: FALSE | CF34: FALSE | CI34: FALSE | CL34: FALSE
A35: 32 | B35: CPO | C35: FALSE | F35: FALSE | I35: FALSE | L35: FALSE | O35: FALSE | R35: FALSE | U35: FALSE | X35: FALSE | AA35: FALSE | AD35: FALSE | AG35: FALSE | AJ35: FALSE | AM35: FALSE | AP35: FALSE | AS35: FALSE | AV35: FALSE | AY35: FALSE | BB35: FALSE | BE35: FALSE | BH35: FALSE | BK35: FALSE | BN35: FALSE | BQ35: TRUE | BR35: Not Reasonable Price | BS35: 14800 | BT35: FALSE | BW35: FALSE | BZ35: FALSE | CC35: FALSE | CF35: FALSE | CI35: FALSE | CL35: FALSE
A36: 33 | B36: Ampok | C36: TRUE | F36: FALSE | I36: FALSE | L36: FALSE | O36: FALSE | R36: FALSE | U36: FALSE | X36: FALSE | AA36: FALSE | AD36: FALSE | AG36: FALSE | AJ36: FALSE | AM36: FALSE | AP36: FALSE | AS36: FALSE | AV36: TRUE | AW36: Sample Sent! | AY36: FALSE | BB36: FALSE | BE36: FALSE | BH36: FALSE | BK36: FALSE | BN36: FALSE | BQ36: FALSE | BT36: FALSE | BW36: FALSE | BZ36: FALSE | CC36: FALSE | CF36: TRUE | CI36: FALSE | CL36: FALSE
B38: Marketing
B39: Purchasing
B40: Marketing
B41: Marketing
...

Sheet Tracking PT Sreeya Sewu Balaraj
A1: SISA PO SREEYA Balaraja
A2: No PO | B2: Tanggal | C2: Nama Bahan | D2: Jumlah PO | E2: Jumlah Dikirim | F2: Sisa PO | G2: Harga | H2: Total (Rupiah) Jumlah Dikirim | I2: Total (Rupiah) Sisa PO | J2: Status
A3: po25000635 | B3: 45731 | C3: Bone Meal | D3: 100000 | E3: 0 | F3: =D3-E3 -> 100000 | G3: 4375 | H3: =IF(E3="","",(SUM($G$3*E3))) -> 0 | I3: =F3*G3 -> 437500000 | J3: =IF(OR(D3="",E3=""),"",IF(F3<=0,"Closed","Open")) -> Open
A4: po25000635 | B4: 45735 | C4: Bone Meal | D4: 100000 | E4: 10050 | F4: =IF(E4="","",(SUM(F3-E4))) -> 89950 | G4: 4375 | H4: =IF(E4="","",(SUM($G$3*E4))) -> 43968750 | I4: =IF(F4="","",(SUM(G3*F4))) -> 393531250 | J4: =IF(OR(F4="",E4=""),"",IF(F4<=0,"Closed","Open")) -> Open
A5: po25000635 | B5: 45736 | C5: Bone Meal | D5: 100000 | E5: 8460 | F5: =IF(E5="","",(SUM(F4-E5))) -> 81490 | G5: 4375 | H5: =IF(E5="","",(SUM($G$3*E5))) -> 37012500 | I5: =IF(F5="","",(SUM(G3*F5))) -> 356518750 | J5: =IF(OR(F5="",E5=""),"",IF(F5<=0,"Closed","Open")) -> Open
A6: po25000635 | B6: 45737 | C6: Bone Meal | D6: 100000 | E6: 9980 | F6: =IF(E6="","",(SUM(F5-E6))) -> 71510 | G6: 4375 | H6: =IF(E6="","",(SUM($G$3*E6))) -> 43662500 | I6: =IF(F6="","",(SUM(G3*F6))) -> 312856250 | J6: =IF(OR(F6="",E6=""),"",IF(F6<=0,"Closed","Open")) -> Open
A7: po25000635 | B7: 45738 | C7: Bone Meal | D7: 100000 | E7: 8900 | F7: =IF(E7="","",(SUM(F6-E7))) -> 62610 | G7: 4375 | H7: =IF(E7="","",(SUM($G$3*E7))) -> 38937500 | I7: =IF(F7="","",(SUM(G3*F7))) -> 273918750 | J7: =IF(OR(F7="",E7=""),"",IF(F7<=0,"Closed","Open")) -> Open
A8: po25000635 | B8: 45740 | C8: Bone Meal | D8: 100000 | E8: 8950 | F8: =IF(E8="","",(SUM(F7-E8))) -> 53660 | G8: 4375 | H8: =IF(E8="","",(SUM($G$3*E8))) -> 39156250 | I8: =IF(F8="","",(SUM(G3*F8))) -> 234762500 | J8: =IF(OR(F8="",E8=""),"",IF(F8<=0,"Closed","Open")) -> Open
A9: po25000635 | B9: 45740 | C9: Bone Meal | D9: 100000 | E9: 9010 | F9: =IF(E9="","",(SUM(F8-E9))) -> 44650 | G9: 4375 | H9: =IF(E9="","",(SUM($G$3*E9))) -> 39418750 | I9: =IF(F9="","",(SUM(G4*F9))) -> 195343750 | J9: =IF(OR(F9="",E9=""),"",IF(F9<=0,"Closed","Open")) -> Open
A10: po25000635 | B10: 45740 | C10: Bone Meal | D10: 100000 | E10: 9990 | F10: =IF(E10="","",(SUM(F9-E10))) -> 34660 | G10: 4375 | H10: =IF(E10="","",(SUM($G$3*E10))) -> 43706250 | I10: =IF(F10="","",(SUM(G5*F10))) -> 151637500 | J10: =IF(OR(F10="",E10=""),"",IF(F10<=0,"Closed","Open")) -> Open
A11: po25000635 | B11: 45740 | C11: Bone Meal | D11: 100000 | E11: 9980 | F11: =IF(E11="","",(SUM(F10-E11))) -> 24680 | G11: 4375 | H11: =IF(E11="","",(SUM($G$3*E11))) -> 43662500 | I11: =IF(F11="","",(SUM(G6*F11))) -> 107975000 | J11: =IF(OR(F11="",E11=""),"",IF(F11<=0,"Closed","Open")) -> Open
A12: po25000635 | B12: 45757 | C12: Bone Meal | D12: 100000 | E12: 8980 | F12: =IF(E12="","",(SUM(F11-E12))) -> 15700 | G12: 4375 | H12: =IF(E12="","",(SUM($G$3*E12))) -> 39287500 | I12: =IF(F12="","",(SUM(G7*F12))) -> 68687500 | J12: =IF(OR(F12="",E12=""),"",IF(F12<=0,"Closed","Open")) -> Open
A13: po25000635 | B13: 45762 | C13: Bone Meal | D13: 100000 | E13: 19960 | F13: =IF(E13="","",(SUM(F12-E13))) -> -4260 | G13: 4000 | H13: =IF(E13="","",(SUM($G$3*E13))) -> 87325000 | I13: =IF(F13="","",(SUM(G8*F13))) -> -18637500 | J13: =IF(OR(F13="",E13=""),"",IF(F13<=0,"Closed","Open")) -> Closed
A14: po25000635 | C14: Bone Meal | D14: 100000 | F14: =IF(E14="","",(SUM(F13-E14))) | G14: 4375 | H14: =IF(E14="","",(SUM($G$3*E14))) | I14: =IF(F14="","",(SUM(G9*F14))) | J14: =IF(OR(F14="",E14=""),"",IF(F14<=0,"Closed","Open"))
A15: po25000635 | C15: Bone Meal | D15: 100000 | F15: =IF(E15="","",(SUM(F14-E15))) | G15: 4375 | H15: =IF(E15="","",(SUM($G$3*E15))) | I15: =IF(F15="","",(SUM(G10*F15))) | J15: =IF(OR(F15="",E15=""),"",IF(F15<=0,"Closed","Open"))
A16: po25000635 | C16: Bone Meal | D16: 100000 | F16: =IF(E16="","",(SUM(F15-E16))) | G16: 4375 | H16: =IF(E16="","",(SUM($G$3*E16))) | I16: =IF(F16="","",(SUM(G11*F16))) | J16: =IF(OR(F16="",E16=""),"",IF(F16<=0,"Closed","Open"))
A17: po25000635 | C17: Bone Meal | D17: 100000 | F17: =IF(E17="","",(SUM(F16-E17))) | G17: 4375 | H17: =IF(E17="","",(SUM($G$3*E17))) | I17: =IF(F17="","",(SUM(G12*F17))) | J17: =IF(OR(F17="",E17=""),"",IF(F17<=0,"Closed","Open"))
A18: po25000631 | B18: 45731 | C18: FTM | D18: 20000 | E18: 0 | F18: 20000 | G18: 8000 | H18: =IF(E18="","",(SUM($G$3*E18))) -> 0 | I18: =F18*G18 -> 160000000 | J18: =IF(OR(D18="",E18=""),"",IF(F18<=0,"Closed","Open")) -> Open
A19: po25000631 | B19: 45733 | C19: FTM | D19: 20000 | E19: 8520 | F19: =IF(E19="","",(SUM(F18-E19))) -> 11480 | G19: 8000 | H19: =IF(E19="","",(SUM($G$3*E19))) -> 37275000 | I19: =IF(F19="","",(SUM(G18*F19))) -> 91840000 | J19: =IF(OR(F19="",E19=""),"",IF(F19<=0,"Closed","Open")) -> Open
A20: po25000631 | B20: 45740 | C20: FTM | D20: 20000 | E20: 8500 | F20: =IF(E20="","",(SUM(F19-E20))) -> 2980 | G20: 8000 | H20: =IF(E20="","",(SUM($G$3*E20))) -> 37187500 | I20: =IF(F20="","",(SUM(G18*F20))) -> 23840000 | J20: =IF(OR(F20="",E20=""),"",IF(F20<=0,"Closed","Open")) -> Open
A21: po25000631 | C21: FTM | D21: 20000 | F21: =IF(E21="","",(SUM(F20-E21))) | G21: 8000 | H21: =IF(E21="","",(SUM($G$3*E21))) | I21: =IF(F21="","",(SUM(G18*F21))) | J21: =IF(OR(F21="",E21=""),"",IF(F21<=0,"Closed","Open"))
A22: po25000631 | C22: FTM | D22: 20000 | F22: =IF(E22="","",(SUM(F21-E22))) | G22: 8000 | H22: =IF(E22="","",(SUM($G$3*E22))) | I22: =IF(F22="","",(SUM(G18*F22))) | J22: =IF(OR(F22="",E22=""),"",IF(F22<=0,"Closed","Open"))
A23: po25000631 | C23: FTM | D23: 20000 | F23: =IF(E23="","",(SUM(F22-E23))) | G23: 8000 | H23: =IF(E23="","",(SUM($G$3*E23))) | I23: =IF(F23="","",(SUM(G18*F23))) | J23: =IF(OR(F23="",E23=""),"",IF(F23<=0,"Closed","Open"))
A24: po25000631 | C24: FTM | D24: 20000 | F24: =IF(E24="","",(SUM(F23-E24))) | G24: 8000 | H24: =IF(E24="","",(SUM($G$3*E24))) | I24: =IF(F24="","",(SUM(G18*F24))) | J24: =IF(OR(F24="",E24=""),"",IF(F24<=0,"Closed","Open"))
A25: po25000631 | C25: FTM | D25: 20000 | F25: =IF(E25="","",(SUM(F24-E25))) | G25: 8000 | H25: =IF(E25="","",(SUM($G$3*E25))) | I25: =IF(F25="","",(SUM(G18*F25))) | J25: =IF(OR(F25="",E25=""),"",IF(F25<=0,"Closed","Open"))
A29: No PO | B29: Tanggal | C29: Nama Bahan | D29: Jumlah PO | E29: Jumlah Dikirim | F29: Sisa PO | G29: Harga | H29: Total (Rupiah) Jumlah Dikirim | I29: Total (Rupiah) Sisa PO | J29: Status
A30: PO25000949 | B30: 45761 | C30: Bone Meal | D30: 50000 | E30: 0 | F30: =D30-E30 -> 50000 | G30: 4400 | H30: =IF(E30="","",(SUM($G$3*E30))) -> 0 | I30: =F30*G30 -> 220000000 | J30: =IF(OR(D30="",E30=""),"",IF(F30<=0,"Closed","Open")) -> Open
A31: PO25000949 | C31: Bone Meal | D31: 50000 | F31: =IF(E31="","",(SUM(F30-E31))) | G31: 4400 | H31: =IF(E31="","",(SUM($G$3*E31))) | I31: =IF(F31="","",(SUM(G30*F31))) | J31: =IF(OR(F31="",E31=""),"",IF(F31<=0,"Closed","Open"))
A32: PO25000949 | C32: Bone Meal | D32: 50000 | F32: =IF(E32="","",(SUM(F31-E32))) | G32: 4400 | H32: =IF(E32="","",(SUM($G$3*E32))) | I32: =IF(F32="","",(SUM(G30*F32))) | J32: =IF(OR(F32="",E32=""),"",IF(F32<=0,"Closed","Open"))
A33: PO25000949 | C33: Bone Meal | D33: 50000 | F33: =IF(E33="","",(SUM(F32-E33))) | G33: 4400 | H33: =IF(E33="","",(SUM($G$3*E33))) | I33: =IF(F33="","",(SUM(G30*F33))) | J33: =IF(OR(F33="",E33=""),"",IF(F33<=0,"Closed","Open"))
A34: PO25000949 | C34: Bone Meal | D34: 50000 | F34: =IF(E34="","",(SUM(F33-E34))) | G34: 4400 | H34: =IF(E34="","",(SUM($G$3*E34))) | I34: =IF(F34="","",(SUM(G30*F34))) | J34: =IF(OR(F34="",E34=""),"",IF(F34<=0,"Closed","Open"))
A35: PO25000949 | C35: Bone Meal | D35: 50000 | F35: =IF(E35="","",(SUM(F34-E35))) | G35: 4400 | H35: =IF(E35="","",(SUM($G$3*E35))) | I35: =IF(F35="","",(SUM(G30*F35))) | J35: =IF(OR(F35="",E35=""),"",IF(F35<=0,"Closed","Open"))
A36: PO25000949 | C36: Bone Meal | D36: 50000 | F36: =IF(E36="","",(SUM(F35-E36))) | G36: 4400 | H36: =IF(E36="","",(SUM($G$3*E36))) | I36: =IF(F36="","",(SUM(G31*F36))) | J36: =IF(OR(F36="",E36=""),"",IF(F36<=0,"Closed","Open"))
A37: PO25000949 | C37: Bone Meal | D37: 50000 | F37: =IF(E37="","",(SUM(F36-E37))) | G37: 4400 | H37: =IF(E37="","",(SUM($G$3*E37))) | I37: =IF(F37="","",(SUM(G32*F37))) | J37: =IF(OR(F37="",E37=""),"",IF(F37<=0,"Closed","Open"))
A38: PO25000949 | C38: Bone Meal | D38: 50000 | F38: =IF(E38="","",(SUM(F37-E38))) | G38: 4400 | H38: =IF(E38="","",(SUM($G$3*E38))) | I38: =IF(F38="","",(SUM(G33*F38))) | J38: =IF(OR(F38="",E38=""),"",IF(F38<=0,"Closed","Open"))
A39: PO25000949 | C39: Bone Meal | D39: 50000 | F39: =IF(E39="","",(SUM(F38-E39))) | G39: 4400 | H39: =IF(E39="","",(SUM($G$3*E39))) | I39: =IF(F39="","",(SUM(G34*F39))) | J39: =IF(OR(F39="",E39=""),"",IF(F39<=0,"Closed","Open"))
A40: PO25000949 | C40: Bone Meal | D40: 50000 | F40: =IF(E40="","",(SUM(F39-E40))) | G40: 4400 | H40: =IF(E40="","",(SUM($G$3*E40))) | I40: =IF(F40="","",(SUM(G35*F40))) | J40: =IF(OR(F40="",E40=""),"",IF(F40<=0,"Closed","Open"))
A41: PO25000949 | C41: Bone Meal | D41: 50000 | F41: =IF(E41="","",(SUM(F40-E41))) | G41: 4400 | H41: =IF(E41="","",(SUM($G$3*E41))) | I41: =IF(F41="","",(SUM(G36*F41))) | J41: =IF(OR(F41="",E41=""),"",IF(F41<=0,"Closed","Open"))
A42: PO25000949 | C42: Bone Meal | D42: 50000 | F42: =IF(E42="","",(SUM(F41-E42))) | G42: 4400 | H42: =IF(E42="","",(SUM($G$3*E42))) | I42: =IF(F42="","",(SUM(G37*F42))) | J42: =IF(OR(F42="",E42=""),"",IF(F42<=0,"Closed","Open"))
A43: PO25000949 | C43: Bone Meal | D43: 50000 | F43: =IF(E43="","",(SUM(F42-E43))) | G43: 4400 | H43: =IF(E43="","",(SUM($G$3*E43))) | I43: =IF(F43="","",(SUM(G38*F43))) | J43: =IF(OR(F43="",E43=""),"",IF(F43<=0,"Closed","Open"))
...

Sheet Tracking PT Sreeya Sewu
A1: SISA PO SREEYA
A2: No PO | B2: Tanggal | C2: Nama Bahan | D2: Jumlah PO | E2: Jumlah Dikirim | F2: Sisa PO | G2: Harga | H2: Total (Rupiah) PO Terkirim | I2: Total (Rupiah) Sisa PO | J2: Status
A3: po25000612 | B3: 45731 | C3: Bone Meal | D3: 50000 | E3: 0 | F3: =D3-E3 -> 50000 | G3: 4300 | H3: =IF(E3="","",(SUM($G$3*E3))) -> 0 | I3: =F3*G3 -> 215000000 | J3: =IF(OR(D3="",E3=""),"",IF(F3<=0,"Closed","Open")) -> Open
B4: 45735 | E4: 8970 | F4: =IF(E4="","",(SUM(F3-E4))) -> 41030 | H4: =IF(E4="","",(SUM($G$3*E4))) -> 38571000 | I4: =IF(F4="","",(SUM(G3*F4))) -> 176429000 | J4: =IF(OR(F4="",E4=""),"",IF(F4<=0,"Closed","Open")) -> Open
B5: 45735 | E5: 9970 | F5: =IF(E5="","",(SUM(F4-E5))) -> 31060 | H5: =IF(E5="","",(SUM($G$3*E5))) -> 42871000 | I5: =IF(F5="","",(SUM(G3*F5))) -> 133558000 | J5: =IF(OR(F5="",E5=""),"",IF(F5<=0,"Closed","Open")) -> Open
B6: 45737 | E6: 10030 | F6: =IF(E6="","",(SUM(F5-E6))) -> 21030 | H6: =IF(E6="","",(SUM($G$3*E6))) -> 43129000 | I6: =IF(F6="","",(SUM(G3*F6))) -> 90429000 | J6: =IF(OR(F6="",E6=""),"",IF(F6<=0,"Closed","Open")) -> Open
B7: 45740 | E7: 8950 | F7: =IF(E7="","",(SUM(F6-E7))) -> 12080 | H7: =IF(E7="","",(SUM($G$3*E7))) -> 38485000 | I7: =IF(F7="","",(SUM(G3*F7))) -> 51944000 | J7: =IF(OR(F7="",E7=""),"",IF(F7<=0,"Closed","Open")) -> Open
F8: =IF(E8="","",(SUM(F7-E8))) | H8: =IF(E8="","",(SUM($G$3*E8))) | I8: =IF(F8="","",(SUM(G3*F8))) | J8: =IF(OR(F8="",E8=""),"",IF(F8<=0,"Closed","Open"))
F9: =IF(E9="","",(SUM(F8-E9))) | H9: =IF(E9="","",(SUM($G$3*E9))) | I9: =IF(F9="","",(SUM(G3*F9))) | J9: =IF(OR(F9="",E9=""),"",IF(F9<=0,"Closed","Open"))
F10: =IF(E10="","",(SUM(F9-E10))) | H10: =IF(E10="","",(SUM($G$3*E10))) | I10: =IF(F10="","",(SUM(G3*F10))) | J10: =IF(OR(F10="",E10=""),"",IF(F10<=0,"Closed","Open"))
A11: po25000413 | B11: 45731 | C11: Bone Meal | D11: 40970 | E11: 0 | F11: 40970 | G11: 4300 | H11: =IF(E11="","",(SUM($G$3*E11))) -> 0 | I11: =F11*G11 -> 176171000 | J11: =IF(OR(D11="",E11=""),"",IF(F11<=0,"Closed","Open")) -> Open
B12: 45733 | E12: 8980 | F12: =IF(E12="","",(SUM(F11-E12))) -> 31990 | H12: =IF(E12="","",(SUM($G$3*E12))) -> 38614000 | I12: =IF(F12="","",(SUM(G11*F12))) -> 137557000 | J12: =IF(OR(F12="",E12=""),"",IF(F12<=0,"Closed","Open")) -> Open
F13: =IF(E13="","",(SUM(F12-E13))) | H13: =IF(E13="","",(SUM($G$3*E13))) | I13: =IF(F13="","",(SUM(G11*F13))) | J13: =IF(OR(F13="",E13=""),"",IF(F13<=0,"Closed","Open"))
F14: =IF(E14="","",(SUM(F13-E14))) | H14: =IF(E14="","",(SUM($G$3*E14))) | I14: =IF(F14="","",(SUM(G11*F14))) | J14: =IF(OR(F14="",E14=""),"",IF(F14<=0,"Closed","Open"))
F15: =IF(E15="","",(SUM(F14-E15))) | H15: =IF(E15="","",(SUM($G$3*E15))) | I15: =IF(F15="","",(SUM(G11*F15))) | J15: =IF(OR(F15="",E15=""),"",IF(F15<=0,"Closed","Open"))
F16: =IF(E16="","",(SUM(F15-E16))) | H16: =IF(E16="","",(SUM($G$3*E16))) | I16: =IF(F16="","",(SUM(G11*F16))) | J16: =IF(OR(F16="",E16=""),"",IF(F16<=0,"Closed","Open"))
F17: =IF(E17="","",(SUM(F16-E17))) | H17: =IF(E17="","",(SUM($G$3*E17))) | I17: =IF(F17="","",(SUM(G11*F17))) | J17: =IF(OR(F17="",E17=""),"",IF(F17<=0,"Closed","Open"))
F18: =IF(E18="","",(SUM(F17-E18))) | H18: =IF(E18="","",(SUM($G$3*E18))) | I18: =IF(F18="","",(SUM(G11*F18))) | J18: =IF(OR(F18="",E18=""),"",IF(F18<=0,"Closed","Open"))
A19: po25000619 | B19: 45731 | C19: Biskuit | D19: 13100 | E19: 0 | F19: =D19-E19 -> 13100 | G19: 3925 | H19: =IF(E19="","",(SUM($G$3*E19))) -> 0 | I19: =F19*G19 -> 51417500 | J19: =IF(OR(F19="",E19=""),"",IF(F19<=0,"Closed","Open")) -> Open
F20: =IF(E20="","",(SUM(F19-E20))) | H20: =IF(E20="","",(SUM($G$3*E20))) | I20: =IF(F20="","",(SUM(G19*F20))) | J20: =IF(OR(F20="",E20=""),"",IF(F20<=0,"Closed","Open"))
F21: =IF(E21="","",(SUM(F20-E21))) | H21: =IF(E21="","",(SUM($G$3*E21))) | I21: =IF(F21="","",(SUM(G19*F21))) | J21: =IF(OR(F21="",E21=""),"",IF(F21<=0,"Closed","Open"))
F22: =IF(E22="","",(SUM(F21-E22))) | H22: =IF(E22="","",(SUM($G$3*E22))) | I22: =IF(F22="","",(SUM(G19*F22))) | J22: =IF(OR(F22="",E22=""),"",IF(F22<=0,"Closed","Open"))
F23: =IF(E23="","",(SUM(F22-E23))) | H23: =IF(E23="","",(SUM($G$3*E23))) | I23: =IF(F23="","",(SUM(G19*F23))) | J23: =IF(OR(F23="",E23=""),"",IF(F23<=0,"Closed","Open"))
F24: =IF(E24="","",(SUM(F23-E24))) | H24: =IF(E24="","",(SUM($G$3*E24))) | I24: =IF(F24="","",(SUM(G19*F24))) | J24: =IF(OR(F24="",E24=""),"",IF(F24<=0,"Closed","Open"))
F25: =IF(E25="","",(SUM(F24-E25))) | H25: =IF(E25="","",(SUM($G$3*E25))) | I25: =IF(F25="","",(SUM(G19*F25))) | J25: =IF(OR(F25="",E25=""),"",IF(F25<=0,"Closed","Open"))
F26: =IF(E26="","",(SUM(F25-E26))) | H26: =IF(E26="","",(SUM($G$3*E26))) | I26: =IF(F26="","",(SUM(G19*F26))) | J26: =IF(OR(F26="",E26=""),"",IF(F26<=0,"Closed","Open"))
A27: po25000346 | B27: 45731 | C27: Mie Kuning | D27: 30370 | E27: 0 | F27: =D27-E27 -> 30370 | G27: 5200 | H27: =IF(E27="","",(SUM($G$3*E27))) -> 0 | I27: =F27*G27 -> 157924000 | J27: =IF(OR(F27="",E27=""),"",IF(F27<=0,"Closed","Open")) -> Open
B28: 45737 | E28: 12150 | F28: =IF(E28="","",(SUM(F27-E28))) -> 18220 | H28: =IF(E28="","",(SUM($G$3*E28))) -> 52245000 | I28: =IF(F28="","",(SUM(G27*F28))) -> 94744000 | J28: =IF(OR(F28="",E28=""),"",IF(F28<=0,"Closed","Open")) -> Open
E29: 15150 | F29: =IF(E29="","",(SUM(F28-E29))) -> 3070 | H29: =IF(E29="","",(SUM($G$3*E29))) -> 65145000 | I29: =IF(F29="","",(SUM(G27*F29))) -> 15964000 | J29: =IF(OR(F29="",E29=""),"",IF(F29<=0,"Closed","Open")) -> Open
F30: =IF(E30="","",(SUM(F29-E30))) | H30: =IF(E30="","",(SUM($G$3*E30))) | I30: =IF(F30="","",(SUM(G27*F30))) | J30: =IF(OR(F30="",E30=""),"",IF(F30<=0,"Closed","Open"))
F31: =IF(E31="","",(SUM(F30-E31))) | H31: =IF(E31="","",(SUM($G$3*E31))) | I31: =IF(F31="","",(SUM(G27*F31))) | J31: =IF(OR(F31="",E31=""),"",IF(F31<=0,"Closed","Open"))
F32: =IF(E32="","",(SUM(F31-E32))) | H32: =IF(E32="","",(SUM($G$3*E32))) | I32: =IF(F32="","",(SUM(G27*F32))) | J32: =IF(OR(F32="",E32=""),"",IF(F32<=0,"Closed","Open"))
F33: =IF(E33="","",(SUM(F32-E33))) | H33: =IF(E33="","",(SUM($G$3*E33))) | I33: =IF(F33="","",(SUM(G27*F33))) | J33: =IF(OR(F33="",E33=""),"",IF(F33<=0,"Closed","Open"))
F34: =IF(E34="","",(SUM(F33-E34))) | H34: =IF(E34="","",(SUM($G$3*E34))) | I34: =IF(F34="","",(SUM(G27*F34))) | J34: =IF(OR(F34="",E34=""),"",IF(F34<=0,"Closed","Open"))
A35: po25000215 | B35: 45731 | C35: Mie Kuning | D35: 10640 | E35: 0 | F35: =D35-E35 -> 10640 | G35: 5100 | H35: =IF(E35="","",(SUM($G$3*E35))) -> 0 | I35: =F35*G35 -> 54264000 | J35: =IF(OR(F35="",E35=""),"",IF(F35<=0,"Closed","Open")) -> Open
F36: =IF(E36="","",(SUM(F35-E36))) | H36: =IF(E36="","",(SUM($G$3*E36))) | I36: =IF(F36="","",(SUM(G35*F36))) | J36: =IF(OR(F36="",E36=""),"",IF(F36<=0,"Closed","Open"))
F37: =IF(E37="","",(SUM(F36-E37))) | H37: =IF(E37="","",(SUM($G$3*E37))) | I37: =IF(F37="","",(SUM(G35*F37))) | J37: =IF(OR(F37="",E37=""),"",IF(F37<=0,"Closed","Open"))
F38: =IF(E38="","",(SUM(F37-E38))) | H38: =IF(E38="","",(SUM($G$3*E38))) | I38: =IF(F38="","",(SUM(G35*F38))) | J38: =IF(OR(F38="",E38=""),"",IF(F38<=0,"Closed","Open"))
F39: =IF(E39="","",(SUM(F38-E39))) | H39: =IF(E39="","",(SUM($G$3*E39))) | I39: =IF(F39="","",(SUM(G35*F39))) | J39: =IF(OR(F39="",E39=""),"",IF(F39<=0,"Closed","Open"))
F40: =IF(E40="","",(SUM(F39-E40))) | H40: =IF(E40="","",(SUM($G$3*E40))) | I40: =IF(F40="","",(SUM(G35*F40))) | J40: =IF(OR(F40="",E40=""),"",IF(F40<=0,"Closed","Open"))
...

Sheet Tracking PT Dinamika Megatama C
A1: SISA PO DMC
A2: No PO | B2: Tanggal | C2: Nama Bahan | D2: Jumlah PO | E2: Jumlah Dikirim | F2: Sisa PO | G2: Harga | H2: Total (Rupiah) Jumlah Pengiriman | I2: Total (Rupiah) Sisa PO | J2: Status
A3: po25001326 | B3: 45731 | C3: Katul | D3: 3850 | E3: 0 | F3: =D3-E3 -> 3850 | G3: 4100 | H3: =IF(E3="","",(SUM($G$3*E3))) -> 0 | I3: =F3*G3 -> 15785000 | J3: =IF(OR(D3="",E3=""),"",IF(F3<=0,"Closed","Open")) -> Open
B4: 45731 | E4: 7860 | F4: =IF(E4="","",(SUM(F3-E4))) -> -4010 | H4: =IF(E4="","",(SUM($G$3*E4))) -> 32226000 | I4: =IF(F4="","",(SUM(G3*F4))) -> -16441000 | J4: =IF(OR(F4="",E4=""),"",IF(F4<=0,"Closed","Open")) -> Closed
F5: =IF(E5="","",(SUM(F4-E5))) | H5: =IF(E5="","",(SUM($G$3*E5))) | I5: =IF(F5="","",(SUM(G3*F5))) | J5: =IF(OR(F5="",E5=""),"",IF(F5<=0,"Closed","Open"))
F6: =IF(E6="","",(SUM(F5-E6))) | H6: =IF(E6="","",(SUM($G$3*E6))) | I6: =IF(F6="","",(SUM(G3*F6))) | J6: =IF(OR(F6="",E6=""),"",IF(F6<=0,"Closed","Open"))
F7: =IF(E7="","",(SUM(F6-E7))) | H7: =IF(E7="","",(SUM($G$3*E7))) | I7: =IF(F7="","",(SUM(G3*F7))) | J7: =IF(OR(F7="",E7=""),"",IF(F7<=0,"Closed","Open"))
F8: =IF(E8="","",(SUM(F7-E8))) | H8: =IF(E8="","",(SUM($G$3*E8))) | I8: =IF(F8="","",(SUM(G3*F8))) | J8: =IF(OR(F8="",E8=""),"",IF(F8<=0,"Closed","Open"))
F9: =IF(E9="","",(SUM(F8-E9))) | H9: =IF(E9="","",(SUM($G$3*E9))) | I9: =IF(F9="","",(SUM(G3*F9))) | J9: =IF(OR(F9="",E9=""),"",IF(F9<=0,"Closed","Open"))
F10: =IF(E10="","",(SUM(F9-E10))) | H10: =IF(E10="","",(SUM($G$3*E10))) | I10: =IF(F10="","",(SUM(G3*F10))) | J10: =IF(OR(F10="",E10=""),"",IF(F10<=0,"Closed","Open"))
A11: po25001855 | B11: 45735 | C11: Kebi | D11: 30000 | E11: 0 | F11: =D11-E11 -> 30000 | G11: 4400 | H11: =IF(E11="","",(SUM($G$3*E11))) -> 0 | I11: =F11*G11 -> 132000000 | J11: =IF(OR(D11="",E11=""),"",IF(F11<=0,"Closed","Open")) -> Open
B12: 45737 | E12: 10130 | F12: =IF(E12="","",(SUM(F11-E12))) -> 19870 | H12: =IF(E12="","",(SUM($G$3*E12))) -> 41533000 | I12: =IF(F12="","",(SUM(G11*F12))) -> 87428000 | J12: =IF(OR(F12="",E12=""),"",IF(F12<=0,"Closed","Open")) -> Open
B13: 45740 | E13: 18170 | F13: =IF(E13="","",(SUM(F12-E13))) -> 1700 | H13: =IF(E13="","",(SUM($G$3*E13))) -> 74497000 | I13: =IF(F13="","",(SUM(G11*F13))) -> 7480000 | J13: =IF(OR(F13="",E13=""),"",IF(F13<=0,"Closed","Open")) -> Open
F14: =IF(E14="","",(SUM(F13-E14))) | H14: =IF(E14="","",(SUM($G$3*E14))) | I14: =IF(F14="","",(SUM(G11*F14))) | J14: =IF(OR(F14="",E14=""),"",IF(F14<=0,"Closed","Open"))
F15: =IF(E15="","",(SUM(F14-E15))) | H15: =IF(E15="","",(SUM($G$3*E15))) | I15: =IF(F15="","",(SUM(G11*F15))) | J15: =IF(OR(F15="",E15=""),"",IF(F15<=0,"Closed","Open"))
F16: =IF(E16="","",(SUM(F15-E16))) | H16: =IF(E16="","",(SUM($G$3*E16))) | I16: =IF(F16="","",(SUM(G11*F16))) | J16: =IF(OR(F16="",E16=""),"",IF(F16<=0,"Closed","Open"))
F17: =IF(E17="","",(SUM(F16-E17))) | H17: =IF(E17="","",(SUM($G$3*E17))) | I17: =IF(F17="","",(SUM(G11*F17))) | J17: =IF(OR(F17="",E17=""),"",IF(F17<=0,"Closed","Open"))
F18: =IF(E18="","",(SUM(F17-E18))) | H18: =IF(E18="","",(SUM($G$3*E18))) | I18: =IF(F18="","",(SUM(G11*F18))) | J18: =IF(OR(F18="",E18=""),"",IF(F18<=0,"Closed","Open"))
A19: po25001856 | B19: 45735 | C19: PKD (Palm Kernel Dehulized) | D19: 50000 | E19: 0 | F19: =D19-E19 -> 50000 | G19: 4100 | H19: =IF(E19="","",(SUM($G$3*E19))) -> 0 | I19: =F19*G19 -> 205000000 | J19: =IF(OR(D19="",E19=""),"",IF(F19<=0,"Closed","Open")) -> Open
F20: =IF(E20="","",(SUM(F19-E20))) | H20: =IF(E20="","",(SUM($G$3*E20))) | I20: =IF(F20="","",(SUM(G19*F20))) | J20: =IF(OR(F20="",E20=""),"",IF(F20<=0,"Closed","Open"))
F21: =IF(E21="","",(SUM(F20-E21))) | H21: =IF(E21="","",(SUM($G$3*E21))) | I21: =IF(F21="","",(SUM(G19*F21))) | J21: =IF(OR(F21="",E21=""),"",IF(F21<=0,"Closed","Open"))
F22: =IF(E22="","",(SUM(F21-E22))) | H22: =IF(E22="","",(SUM($G$3*E22))) | I22: =IF(F22="","",(SUM(G19*F22))) | J22: =IF(OR(F22="",E22=""),"",IF(F22<=0,"Closed","Open"))
F23: =IF(E23="","",(SUM(F22-E23))) | H23: =IF(E23="","",(SUM($G$3*E23))) | I23: =IF(F23="","",(SUM(G19*F23))) | J23: =IF(OR(F23="",E23=""),"",IF(F23<=0,"Closed","Open"))
F24: =IF(E24="","",(SUM(F23-E24))) | H24: =IF(E24="","",(SUM($G$3*E24))) | I24: =IF(F24="","",(SUM(G19*F24))) | J24: =IF(OR(F24="",E24=""),"",IF(F24<=0,"Closed","Open"))
F25: =IF(E25="","",(SUM(F24-E25))) | H25: =IF(E25="","",(SUM($G$3*E25))) | I25: =IF(F25="","",(SUM(G19*F25))) | J25: =IF(OR(F25="",E25=""),"",IF(F25<=0,"Closed","Open"))
F26: =IF(E26="","",(SUM(F25-E26))) | H26: =IF(E26="","",(SUM($G$3*E26))) | I26: =IF(F26="","",(SUM(G19*F26))) | J26: =IF(OR(F26="",E26=""),"",IF(F26<=0,"Closed","Open"))

Sheet Tracking PT Matahari Sakti
D1: PO MS
A2: No PO | B2: Tanggal | C2: Nama Bahan | D2: Jumlah PO | E2: Jumlah Dikirim | F2: Sisa PO | G2: Harga | H2: Total (Rupiah) Jumlah Dikirim | I2: Total (Rupiah) Sisa PO | J2: Status
A3: po25000635 | B3: 45735 | C3: Biskuit | D3: 125000 | E3: 0 | F3: =D3-E3 -> 125000 | G3: 4200 | H3: =IF(E3="","",(SUM($G$3*E3))) -> 0 | I3: =F3*G3 -> 525000000 | J3: =IF(OR(D3="",E3=""),"",IF(F3<=0,"Closed","Open")) -> Open
A4: po25000635 | B4: 45741 | C4: Biskuit | D4: 125000 | E4: 8496.06 | F4: =IF(E4="","",(SUM(F3-E4))) -> 116503.94 | G4: 4200 | H4: =IF(E4="","",(SUM($G$3*E4))) -> 35683452 | I4: =IF(F4="","",(SUM(G3*F4))) -> 489316548 | J4: =IF(OR(F4="",E4=""),"",IF(F4<=0,"Closed","Open")) -> Open
A5: po25000635 | B5: 45744 | C5: Biskuit | D5: 125000 | E5: 8656.06 | F5: =IF(E5="","",(SUM(F4-E5))) -> 107847.88 | G5: 4200 | H5: =IF(E5="","",(SUM($G$3*E5))) -> 36355452 | I5: =IF(F5="","",(SUM(G3*F5))) -> 452961096 | J5: =IF(OR(F5="",E5=""),"",IF(F5<=0,"Closed","Open")) -> Open
A6: po25000635 | B6: 45754 | C6: Biskuit | D6: 125000 | E6: 8566.06 | F6: =IF(E6="","",(SUM(F5-E6))) -> 99281.82 | G6: 4200 | H6: =IF(E6="","",(SUM($G$3*E6))) -> 35977452 | I6: =IF(F6="","",(SUM(G3*F6))) -> 416983644 | J6: =IF(OR(F6="",E6=""),"",IF(F6<=0,"Closed","Open")) -> Open
A7: po25000635 | B7: 45754 | C7: Biskuit | D7: 125000 | E7: 8566.06 | F7: =IF(E7="","",(SUM(F6-E7))) -> 90715.76 | G7: 4200 | H7: =IF(E7="","",(SUM($G$3*E7))) -> 35977452 | I7: =IF(F7="","",(SUM(G3*F7))) -> 381006192 | J7: =IF(OR(F7="",E7=""),"",IF(F7<=0,"Closed","Open")) -> Open
A8: po25000635 | B8: 45756 | C8: Biskuit | D8: 125000 | E8: 8566.06 | F8: =IF(E8="","",(SUM(F7-E8))) -> 82149.7 | G8: 4200 | H8: =IF(E8="","",(SUM($G$3*E8))) -> 35977452 | I8: =IF(F8="","",(SUM(G3*F8))) -> 345028740 | J8: =IF(OR(F8="",E8=""),"",IF(F8<=0,"Closed","Open")) -> Open
A9: po25000635 | B9: 45757 | C9: Biskuit | D9: 125000 | E9: 8556.06 | F9: =IF(E9="","",(SUM(F8-E9))) -> 73593.64 | G9: 4200 | H9: =IF(E9="","",(SUM($G$3*E9))) -> 35935452 | I9: =IF(F9="","",(SUM(G3*F9))) -> 309093288 | J9: =IF(OR(F9="",E9=""),"",IF(F9<=0,"Closed","Open")) -> Open
A10: po25000635 | B10: 45758 | C10: Biskuit | D10: 125000 | E10: 8506.06 | F10: =IF(E10="","",(SUM(F9-E10))) -> 65087.58 | G10: 4200 | H10: =IF(E10="","",(SUM($G$3*E10))) -> 35725452 | I10: =IF(F10="","",(SUM(G3*F10))) -> 273367836 | J10: =IF(OR(F10="",E10=""),"",IF(F10<=0,"Closed","Open")) -> Open
A11: po25000635 | B11: 45757 | C11: Biskuit | D11: 125000 | E11: 8556.06 | F11: =IF(E11="","",(SUM(F10-E11))) -> 56531.52 | G11: 4200 | H11: =IF(E11="","",(SUM($G$3*E11))) -> 35935452 | I11: =IF(F11="","",(SUM(G5*F11))) -> 237432384 | J11: =IF(OR(F11="",E11=""),"",IF(F11<=0,"Closed","Open")) -> Open
A12: po25000635 | B12: 45758 | C12: Biskuit | D12: 125000 | E12: 8506.06 | F12: =IF(E12="","",(SUM(F11-E12))) -> 48025.46 | G12: 4200 | H12: =IF(E12="","",(SUM($G$3*E12))) -> 35725452 | I12: =IF(F12="","",(SUM(G5*F12))) -> 201706932 | J12: =IF(OR(F12="",E12=""),"",IF(F12<=0,"Closed","Open")) -> Open
A13: po25000635 | C13: Biskuit | D13: 125000 | F13: =IF(E13="","",(SUM(F12-E13))) | G13: 4200 | H13: =IF(E13="","",(SUM($G$3*E13))) | I13: =IF(F13="","",(SUM(G7*F13))) | J13: =IF(OR(F13="",E13=""),"",IF(F13<=0,"Closed","Open"))
A14: po25000635 | C14: Biskuit | D14: 125000 | F14: =IF(E14="","",(SUM(F13-E14))) | G14: 4200 | H14: =IF(E14="","",(SUM($G$3*E14))) | I14: =IF(F14="","",(SUM(G7*F14))) | J14: =IF(OR(F14="",E14=""),"",IF(F14<=0,"Closed","Open"))
A15: po25000635 | C15: Biskuit | D15: 125000 | F15: =IF(E15="","",(SUM(F14-E15))) | G15: 4200 | H15: =IF(E15="","",(SUM($G$3*E15))) | I15: =IF(F15="","",(SUM(G9*F15))) | J15: =IF(OR(F15="",E15=""),"",IF(F15<=0,"Closed","Open"))
A16: po25000635 | C16: Biskuit | D16: 125000 | F16: =IF(E16="","",(SUM(F15-E16))) | G16: 4200 | H16: =IF(E16="","",(SUM($G$3*E16))) | I16: =IF(F16="","",(SUM(G9*F16))) | J16: =IF(OR(F16="",E16=""),"",IF(F16<=0,"Closed","Open"))
A17: po25000635 | C17: Biskuit | D17: 125000 | F17: =IF(E17="","",(SUM(F16-E17))) | G17: 4200 | H17: =IF(E17="","",(SUM($G$3*E17))) | I17: =IF(F17="","",(SUM(G11*F17))) | J17: =IF(OR(F17="",E17=""),"",IF(F17<=0,"Closed","Open"))
A18: po25000635 | C18: Biskuit | D18: 125000 | F18: =IF(E18="","",(SUM(F17-E18))) | G18: 4200 | H18: =IF(E18="","",(SUM($G$3*E18))) | I18: =IF(F18="","",(SUM(G11*F18))) | J18: =IF(OR(F18="",E18=""),"",IF(F18<=0,"Closed","Open"))
A19: po25000635 | C19: Biskuit | D19: 125000 | F19: =IF(E19="","",(SUM(F18-E19))) | G19: 4200 | H19: =IF(E19="","",(SUM($G$3*E19))) | I19: =IF(F19="","",(SUM(G13*F19))) | J19: =IF(OR(F19="",E19=""),"",IF(F19<=0,"Closed","Open"))
A20: po25000635 | C20: Biskuit | D20: 125000 | F20: =IF(E20="","",(SUM(F19-E20))) | G20: 4200 | H20: =IF(E20="","",(SUM($G$3*E20))) | I20: =IF(F20="","",(SUM(G13*F20))) | J20: =IF(OR(F20="",E20=""),"",IF(F20<=0,"Closed","Open"))
A21: po25000635 | C21: Biskuit | D21: 125000 | F21: =IF(E21="","",(SUM(F20-E21))) | G21: 4200 | H21: =IF(E21="","",(SUM($G$3*E21))) | I21: =IF(F21="","",(SUM(G15*F21))) | J21: =IF(OR(F21="",E21=""),"",IF(F21<=0,"Closed","Open"))
A22: po25000635 | C22: Biskuit | D22: 125000 | F22: =IF(E22="","",(SUM(F21-E22))) | G22: 4200 | H22: =IF(E22="","",(SUM($G$3*E22))) | I22: =IF(F22="","",(SUM(G15*F22))) | J22: =IF(OR(F22="",E22=""),"",IF(F22<=0,"Closed","Open"))
A24: No PO | B24: Tanggal | C24: Nama Bahan | D24: Jumlah PO | E24: Jumlah Dikirim | F24: Sisa PO | G24: Harga | H24: Total (Rupiah) Jumlah Dikirim | I24: Total (Rupiah) Sisa PO | J24: Status
A25: PO-250400314 | B25: 45762 | C25: Katul | D25: 100000 | E25: 0 | F25: =D25-E25 -> 100000 | G25: 3075 | H25: =IF(E25="","",(SUM($G$3*E25))) -> 0 | I25: =F25*G25 -> 307500000 | J25: =IF(OR(D25="",E25=""),"",IF(F25<=0,"Closed","Open")) -> Open
A26: PO-250400314 | C26: Katul | D26: 100000 | F26: =IF(E26="","",(SUM(F25-E26))) | G26: 3075 | H26: =IF(E26="","",(SUM($G$3*E26))) | I26: =IF(F26="","",(SUM(G25*F26))) | J26: =IF(OR(F26="",E26=""),"",IF(F26<=0,"Closed","Open"))
A27: PO-250400314 | C27: Katul | D27: 100000 | F27: =IF(E27="","",(SUM(F26-E27))) | G27: 3075 | H27: =IF(E27="","",(SUM($G$3*E27))) | I27: =IF(F27="","",(SUM(G25*F27))) | J27: =IF(OR(F27="",E27=""),"",IF(F27<=0,"Closed","Open"))
A28: PO-250400314 | C28: Katul | D28: 100000 | F28: =IF(E28="","",(SUM(F27-E28))) | G28: 3075 | H28: =IF(E28="","",(SUM($G$3*E28))) | I28: =IF(F28="","",(SUM(G25*F28))) | J28: =IF(OR(F28="",E28=""),"",IF(F28<=0,"Closed","Open"))
A29: PO-250400314 | C29: Katul | D29: 100000 | F29: =IF(E29="","",(SUM(F28-E29))) | G29: 3075 | H29: =IF(E29="","",(SUM($G$3*E29))) | I29: =IF(F29="","",(SUM(G25*F29))) | J29: =IF(OR(F29="",E29=""),"",IF(F29<=0,"Closed","Open"))
A30: PO-250400314 | C30: Katul | D30: 100000 | F30: =IF(E30="","",(SUM(F29-E30))) | G30: 3075 | H30: =IF(E30="","",(SUM($G$3*E30))) | I30: =IF(F30="","",(SUM(G25*F30))) | J30: =IF(OR(F30="",E30=""),"",IF(F30<=0,"Closed","Open"))
A31: PO-250400314 | C31: Katul | D31: 100000 | F31: =IF(E31="","",(SUM(F30-E31))) | G31: 3075 | H31: =IF(E31="","",(SUM($G$3*E31))) | I31: =IF(F31="","",(SUM(G25*F31))) | J31: =IF(OR(F31="",E31=""),"",IF(F31<=0,"Closed","Open"))
A32: PO-250400314 | C32: Katul | D32: 100000 | F32: =IF(E32="","",(SUM(F31-E32))) | G32: 3075 | H32: =IF(E32="","",(SUM($G$3*E32))) | I32: =IF(F32="","",(SUM(G25*F32))) | J32: =IF(OR(F32="",E32=""),"",IF(F32<=0,"Closed","Open"))
A33: PO-250400314 | C33: Katul | D33: 100000 | F33: =IF(E33="","",(SUM(F32-E33))) | G33: 3075 | H33: =IF(E33="","",(SUM($G$3*E33))) | I33: =IF(F33="","",(SUM(G27*F33))) | J33: =IF(OR(F33="",E33=""),"",IF(F33<=0,"Closed","Open"))
A34: PO-250400314 | C34: Katul | D34: 100000 | F34: =IF(E34="","",(SUM(F33-E34))) | G34: 3075 | H34: =IF(E34="","",(SUM($G$3*E34))) | I34: =IF(F34="","",(SUM(G27*F34))) | J34: =IF(OR(F34="",E34=""),"",IF(F34<=0,"Closed","Open"))
A35: PO-250400314 | C35: Katul | D35: 100000 | F35: =IF(E35="","",(SUM(F34-E35))) | G35: 3075 | H35: =IF(E35="","",(SUM($G$3*E35))) | I35: =IF(F35="","",(SUM(G29*F35))) | J35: =IF(OR(F35="",E35=""),"",IF(F35<=0,"Closed","Open"))
A36: PO-250400314 | C36: Katul | D36: 100000 | F36: =IF(E36="","",(SUM(F35-E36))) | G36: 3075 | H36: =IF(E36="","",(SUM($G$3*E36))) | I36: =IF(F36="","",(SUM(G29*F36))) | J36: =IF(OR(F36="",E36=""),"",IF(F36<=0,"Closed","Open"))
A37: PO-250400314 | C37: Katul | D37: 100000 | F37: =IF(E37="","",(SUM(F36-E37))) | G37: 3075 | H37: =IF(E37="","",(SUM($G$3*E37))) | I37: =IF(F37="","",(SUM(G31*F37))) | J37: =IF(OR(F37="",E37=""),"",IF(F37<=0,"Closed","Open"))
A38: PO-250400314 | C38: Katul | D38: 100000 | F38: =IF(E38="","",(SUM(F37-E38))) | G38: 3075 | H38: =IF(E38="","",(SUM($G$3*E38))) | I38: =IF(F38="","",(SUM(G31*F38))) | J38: =IF(OR(F38="",E38=""),"",IF(F38<=0,"Closed","Open"))
A39: PO-250400314 | C39: Katul | D39: 100000 | F39: =IF(E39="","",(SUM(F38-E39))) | G39: 3075 | H39: =IF(E39="","",(SUM($G$3*E39))) | I39: =IF(F39="","",(SUM(G33*F39))) | J39: =IF(OR(F39="",E39=""),"",IF(F39<=0,"Closed","Open"))
A40: PO-250400314 | C40: Katul | D40: 100000 | F40: =IF(E40="","",(SUM(F39-E40))) | G40: 3075 | H40: =IF(E40="","",(SUM($G$3*E40))) | I40: =IF(F40="","",(SUM(G33*F40))) | J40: =IF(OR(F40="",E40=""),"",IF(F40<=0,"Closed","Open"))
A41: PO-250400314 | C41: Katul | D41: 100000 | F41: =IF(E41="","",(SUM(F40-E41))) | G41: 3075 | H41: =IF(E41="","",(SUM($G$3*E41))) | I41: =IF(F41="","",(SUM(G35*F41))) | J41: =IF(OR(F41="",E41=""),"",IF(F41<=0,"Closed","Open"))
...

Sheet Tracking CJ Serang
A1: SISA PO CJ Serang
A2: No PO | B2: Tanggal | C2: Nama Bahan | D2: Jumlah PO | E2: Jumlah Dikirim | F2: Sisa PO | G2: Harga | H2: Total (Rupiah) Jumlah Dikirim | I2: Total (Rupiah) Sisa PO | J2: Status
A3: 5500507536 | B3: 45731 | C3: Biskuit | D3: 82885 | E3: 0 | F3: =D3-E3 -> 82885 | G3: 4250 | H3: =IF(E3="","",(SUM($G$3*E3))) -> 0 | I3: =F3*G3 -> 352261250 | J3: =IF(OR(D3="",E3=""),"",IF(F3<=0,"Closed","Open")) -> Open
B4: 45731 | E4: 8548 | F4: =IF(E4="","",(SUM(F3-E4))) -> 74337 | H4: =IF(E4="","",(SUM($G$3*E4))) -> 36329000 | I4: =IF(F4="","",(SUM(G3*F4))) -> 315932250 | J4: =IF(OR(F4="",E4=""),"",IF(F4<=0,"Closed","Open")) -> Open
B5: 45738 | E5: 8558 | F5: =IF(E5="","",(SUM(F4-E5))) -> 65779 | H5: =IF(E5="","",(SUM($G$3*E5))) -> 36371500 | I5: =IF(F5="","",(SUM(G3*F5))) -> 279560750 | J5: =IF(OR(F5="",E5=""),"",IF(F5<=0,"Closed","Open")) -> Open
B6: 45740 | E6: 4151 | F6: =IF(E6="","",(SUM(F5-E6))) -> 61628 | H6: =IF(E6="","",(SUM($G$3*E6))) -> 17641750 | I6: =IF(F6="","",(SUM(G3*F6))) -> 261919000 | J6: =IF(OR(F6="",E6=""),"",IF(F6<=0,"Closed","Open")) -> Open
B7: 45753 | E7: 3127 | F7: =IF(E7="","",(SUM(F6-E7))) -> 58501 | H7: =IF(E7="","",(SUM($G$3*E7))) -> 13289750 | I7: =IF(F7="","",(SUM(G3*F7))) -> 248629250 | J7: =IF(OR(F7="",E7=""),"",IF(F7<=0,"Closed","Open")) -> Open
B8: 45754 | E8: 7812 | F8: =IF(E8="","",(SUM(F7-E8))) -> 50689 | H8: =IF(E8="","",(SUM($G$3*E8))) -> 33201000 | I8: =IF(F8="","",(SUM(G3*F8))) -> 215428250 | J8: =IF(OR(F8="",E8=""),"",IF(F8<=0,"Closed","Open")) -> Open
F9: =IF(E9="","",(SUM(F8-E9))) | H9: =IF(E9="","",(SUM($G$3*E9))) | I9: =IF(F9="","",(SUM(G3*F9))) | J9: =IF(OR(F9="",E9=""),"",IF(F9<=0,"Closed","Open"))
F10: =IF(E10="","",(SUM(F9-E10))) | H10: =IF(E10="","",(SUM($G$3*E10))) | I10: =IF(F10="","",(SUM(G3*F10))) | J10: =IF(OR(F10="",E10=""),"",IF(F10<=0,"Closed","Open"))
A21: No PO | B21: Tanggal | C21: Nama Bahan | D21: Jumlah PO | E21: Jumlah Dikirim | F21: Sisa PO | G21: Harga | H21: Total (Rupiah) Jumlah Dikirim | I21: Total (Rupiah) Sisa PO | J21: Status
A22: 5500531848 | B22: 45764 | C22: Katul | D22: 100000 | E22: 0 | F22: =D22-E22 -> 100000 | G22: 3200 | H22: =IF(E22="","",(SUM($G$3*E22))) -> 0 | I22: =F22*G22 -> 320000000 | J22: =IF(OR(D22="",E22=""),"",IF(F22<=0,"Closed","Open")) -> Open
F23: =IF(E23="","",(SUM(F22-E23))) | H23: =IF(E23="","",(SUM($G$3*E23))) | I23: =IF(F23="","",(SUM(G22*F23))) | J23: =IF(OR(F23="",E23=""),"",IF(F23<=0,"Closed","Open"))
F24: =IF(E24="","",(SUM(F23-E24))) | H24: =IF(E24="","",(SUM($G$3*E24))) | I24: =IF(F24="","",(SUM(G22*F24))) | J24: =IF(OR(F24="",E24=""),"",IF(F24<=0,"Closed","Open"))
F25: =IF(E25="","",(SUM(F24-E25))) | H25: =IF(E25="","",(SUM($G$3*E25))) | I25: =IF(F25="","",(SUM(G22*F25))) | J25: =IF(OR(F25="",E25=""),"",IF(F25<=0,"Closed","Open"))
F26: =IF(E26="","",(SUM(F25-E26))) | H26: =IF(E26="","",(SUM($G$3*E26))) | I26: =IF(F26="","",(SUM(G22*F26))) | J26: =IF(OR(F26="",E26=""),"",IF(F26<=0,"Closed","Open"))
F27: =IF(E27="","",(SUM(F26-E27))) | H27: =IF(E27="","",(SUM($G$3*E27))) | I27: =IF(F27="","",(SUM(G22*F27))) | J27: =IF(OR(F27="",E27=""),"",IF(F27<=0,"Closed","Open"))
F28: =IF(E28="","",(SUM(F27-E28))) | H28: =IF(E28="","",(SUM($G$3*E28))) | I28: =IF(F28="","",(SUM(G22*F28))) | J28: =IF(OR(F28="",E28=""),"",IF(F28<=0,"Closed","Open"))
F29: =IF(E29="","",(SUM(F28-E29))) | H29: =IF(E29="","",(SUM($G$3*E29))) | I29: =IF(F29="","",(SUM(G22*F29))) | J29: =IF(OR(F29="",E29=""),"",IF(F29<=0,"Closed","Open"))
A32: No PO | B32: Tanggal | C32: Nama Bahan | D32: Jumlah PO | E32: Jumlah Dikirim | F32: Sisa PO | G32: Harga | H32: Total (Rupiah) Jumlah Dikirim | I32: Total (Rupiah) Sisa PO | J32: Status
A33: 5500537493 | B33: 45797 | C33: Katul | D33: 100000 | E33: 0 | F33: =D33-E33 -> 100000 | G33: 3250 | H33: =IF(E33="","",(SUM($G$3*E33))) -> 0 | I33: =F33*G33 -> 325000000 | J33: =IF(OR(D33="",E33=""),"",IF(F33<=0,"Closed","Open")) -> Open
F34: =IF(E34="","",(SUM(F33-E34))) | H34: =IF(E34="","",(SUM($G$3*E34))) | I34: =IF(F34="","",(SUM(G33*F34))) | J34: =IF(OR(F34="",E34=""),"",IF(F34<=0,"Closed","Open"))
F35: =IF(E35="","",(SUM(F34-E35))) | H35: =IF(E35="","",(SUM($G$3*E35))) | I35: =IF(F35="","",(SUM(G33*F35))) | J35: =IF(OR(F35="",E35=""),"",IF(F35<=0,"Closed","Open"))
F36: =IF(E36="","",(SUM(F35-E36))) | H36: =IF(E36="","",(SUM($G$3*E36))) | I36: =IF(F36="","",(SUM(G33*F36))) | J36: =IF(OR(F36="",E36=""),"",IF(F36<=0,"Closed","Open"))
F37: =IF(E37="","",(SUM(F36-E37))) | H37: =IF(E37="","",(SUM($G$3*E37))) | I37: =IF(F37="","",(SUM(G33*F37))) | J37: =IF(OR(F37="",E37=""),"",IF(F37<=0,"Closed","Open"))
F38: =IF(E38="","",(SUM(F37-E38))) | H38: =IF(E38="","",(SUM($G$3*E38))) | I38: =IF(F38="","",(SUM(G33*F38))) | J38: =IF(OR(F38="",E38=""),"",IF(F38<=0,"Closed","Open"))
F39: =IF(E39="","",(SUM(F38-E39))) | H39: =IF(E39="","",(SUM($G$3*E39))) | I39: =IF(F39="","",(SUM(G33*F39))) | J39: =IF(OR(F39="",E39=""),"",IF(F39<=0,"Closed","Open"))
F40: =IF(E40="","",(SUM(F39-E40))) | H40: =IF(E40="","",(SUM($G$3*E40))) | I40: =IF(F40="","",(SUM(G33*F40))) | J40: =IF(OR(F40="",E40=""),"",IF(F40<=0,"Closed","Open"))

Sheet Tracking CJ Jateng
A1: SISA PO CJ Jateng
A2: No PO | B2: Tanggal | C2: Nama Bahan | D2: Jumlah PO | E2: Jumlah Dikirim | F2: Sisa PO | G2: Harga | H2: Total (Rupiah) Jumlah Dikirim | I2: Total (Rupiah) Sisa PO | J2: Status
A3: 5500437612 | B3: 45731 | C3: Biskuit | D3: 33943 | E3: 0 | F3: =D3-E3 -> 33943 | G3: 4250 | H3: =IF(E3="","",(SUM($G$3*E3))) -> 0 | I3: =F3*G3 -> 144257750 | J3: =IF(OR(D3="",E3=""),"",IF(F3<=0,"Closed","Open")) -> Open
F4: =IF(E4="","",(SUM(F3-E4))) | H4: =IF(E4="","",(SUM($G$3*E4))) | I4: =IF(F4="","",(SUM(G3*F4))) | J4: =IF(OR(F4="",E4=""),"",IF(F4<=0,"Closed","Open"))
F5: =IF(E5="","",(SUM(F4-E5))) | H5: =IF(E5="","",(SUM($G$3*E5))) | I5: =IF(F5="","",(SUM(G3*F5))) | J5: =IF(OR(F5="",E5=""),"",IF(F5<=0,"Closed","Open"))
F6: =IF(E6="","",(SUM(F5-E6))) | H6: =IF(E6="","",(SUM($G$3*E6))) | I6: =IF(F6="","",(SUM(G3*F6))) | J6: =IF(OR(F6="",E6=""),"",IF(F6<=0,"Closed","Open"))
F7: =IF(E7="","",(SUM(F6-E7))) | H7: =IF(E7="","",(SUM($G$3*E7))) | I7: =IF(F7="","",(SUM(G3*F7))) | J7: =IF(OR(F7="",E7=""),"",IF(F7<=0,"Closed","Open"))
F8: =IF(E8="","",(SUM(F7-E8))) | H8: =IF(E8="","",(SUM($G$3*E8))) | I8: =IF(F8="","",(SUM(G3*F8))) | J8: =IF(OR(F8="",E8=""),"",IF(F8<=0,"Closed","Open"))
F9: =IF(E9="","",(SUM(F8-E9))) | H9: =IF(E9="","",(SUM($G$3*E9))) | I9: =IF(F9="","",(SUM(G3*F9))) | J9: =IF(OR(F9="",E9=""),"",IF(F9<=0,"Closed","Open"))
F10: =IF(E10="","",(SUM(F9-E10))) | H10: =IF(E10="","",(SUM($G$3*E10))) | I10: =IF(F10="","",(SUM(G3*F10))) | J10: =IF(OR(F10="",E10=""),"",IF(F10<=0,"Closed","Open"))
A13: No PO | B13: Tanggal | C13: Nama Bahan | D13: Jumlah PO | E13: Jumlah Dikirim | F13: Sisa PO | G13: Harga | H13: Total (Rupiah) Jumlah Dikirim | I13: Total (Rupiah) Sisa PO | J13: Status
A14: 5500531850 | B14: 45764 | C14: Katul | D14: 100000 | E14: 0 | F14: =D14-E14 -> 100000 | G14: 3350 | H14: =IF(E14="","",(SUM($G$3*E14))) -> 0 | I14: =F14*G14 -> 335000000 | J14: =IF(OR(D14="",E14=""),"",IF(F14<=0,"Closed","Open")) -> Open
F15: =IF(E15="","",(SUM(F14-E15))) | H15: =IF(E15="","",(SUM($G$3*E15))) | I15: =IF(F15="","",(SUM(G14*F15))) | J15: =IF(OR(F15="",E15=""),"",IF(F15<=0,"Closed","Open"))
F16: =IF(E16="","",(SUM(F15-E16))) | H16: =IF(E16="","",(SUM($G$3*E16))) | I16: =IF(F16="","",(SUM(G14*F16))) | J16: =IF(OR(F16="",E16=""),"",IF(F16<=0,"Closed","Open"))
F17: =IF(E17="","",(SUM(F16-E17))) | H17: =IF(E17="","",(SUM($G$3*E17))) | I17: =IF(F17="","",(SUM(G14*F17))) | J17: =IF(OR(F17="",E17=""),"",IF(F17<=0,"Closed","Open"))
F18: =IF(E18="","",(SUM(F17-E18))) | H18: =IF(E18="","",(SUM($G$3*E18))) | I18: =IF(F18="","",(SUM(G14*F18))) | J18: =IF(OR(F18="",E18=""),"",IF(F18<=0,"Closed","Open"))
F19: =IF(E19="","",(SUM(F18-E19))) | H19: =IF(E19="","",(SUM($G$3*E19))) | I19: =IF(F19="","",(SUM(G14*F19))) | J19: =IF(OR(F19="",E19=""),"",IF(F19<=0,"Closed","Open"))
F20: =IF(E20="","",(SUM(F19-E20))) | H20: =IF(E20="","",(SUM($G$3*E20))) | I20: =IF(F20="","",(SUM(G14*F20))) | J20: =IF(OR(F20="",E20=""),"",IF(F20<=0,"Closed","Open"))
F21: =IF(E21="","",(SUM(F20-E21))) | H21: =IF(E21="","",(SUM($G$3*E21))) | I21: =IF(F21="","",(SUM(G14*F21))) | J21: =IF(OR(F21="",E21=""),"",IF(F21<=0,"Closed","Open"))

Sheet Tracking PT CJ  Jombang
A1: SISA PO CJ Jombang | O1: Suplier | P1: Pembagian PO | Q1: Harga Supplier | R1: Harga Jual | S1: Persentase | T1: Total
A2: No PO | B2: Tanggal | C2: Nama Bahan | D2: Jumlah PO | E2: Jumlah Dikirim | F2: Sisa PO | G2: Harga | H2: Total (Rupiah) Jumlah Pengiriman | I2: Total (Rupiah) Sisa PO | J2: Status | O2: Pak Tris | P2: 75000 | Q2: 3000 | R2: 3300 | S2: =(R2-Q2)/(R2*100%) -> 0.090909091 | T2: =P2*Q2 -> 225000000
